<?xml version='1.0' ?>
{%- set model_name = 'nxp_cupcar' if model_name == 'NotSet' else model_name -%}
{%- set sdf_version = '1.5' if sdf_version == 'NotSet' else sdf_version -%}
{%- set low_polycountframe = 1 -%}
{%- set low_polycountwheel = 1 -%}
{%- set pixy2_cmucam5 = 1 -%}
<sdf version='{{ sdf_version }}'>
  <model name='{{ model_name }}'>
  	<pose>0 0 .05 0 0 0</pose>
    <static>false</static>
    <link name='{{ model_name }}_frame_link'>
      <inertial>
        <pose>-.15 0 0 0 0 0</pose>
        <mass>20.0</mass>
        <inertia>
          <ixx>0.4</ixx>
          <ixy>0.0</ixy>
          <ixz>0.0</ixz>
          <iyy>0.4</iyy>
          <iyz>0.0</iyz>
          <izz>0.5</izz>
        </inertia>
      </inertial>

    {%- if low_polycountframe != 1 -%}
      <visual name='{{ model_name }}_frame_carbon_visual'>
        <pose>-0.145 0 .146 1.57079632679 0 1.57079632679</pose>
        <geometry>
          <mesh>
            <uri>model://nxp_cupcar/meshes/CUPCarCarbonFiber.stl</uri>
            <scale>0.001 0.001 0.001</scale>
          </mesh>
        </geometry>
        <material>
          <script>
            <name>Gazebo/Black</name>
            <uri>file://media/materials/scripts/gazebo.material</uri>
          </script>
        </material>
      </visual>
      <visual name='{{ model_name }}_frame_metal_visual'>
        <pose>-0.145 0 .146 1.57079632679 0 1.57079632679</pose>
        <geometry>
          <mesh>
            <uri>model://nxp_cupcar/meshes/CUPCarMetalPartsNoSteerNoScrews.stl</uri>
            <scale>0.001 0.001 0.001</scale>
          </mesh>
        </geometry>
        <material>
          <script>
            <name>Gazebo/Grey</name>
            <uri>file://media/materials/scripts/gazebo.material</uri>
          </script>
        </material>
      </visual>
      <visual name='{{ model_name }}_frame_bumper_servo_visual'>
        <pose>-0.145 0 .146 1.57079632679 0 1.57079632679</pose>
        <geometry>
          <mesh>
            <uri>model://nxp_cupcar/meshes/CUPCarServoBumper.stl</uri>
            <scale>0.001 0.001 0.001</scale>
          </mesh>
        </geometry>
        <material>
          <script>
            <name>Gazebo/DarkGrey</name>
            <uri>file://media/materials/scripts/gazebo.material</uri>
          </script>
        </material>
      </visual>
    {% endif %}
    {%- if low_polycountframe == 1 -%}  
      <visual name='{{ model_name }}_frame_collision_visual'>
        <pose>0 0 0 0 0 1.57079632679</pose>
        <geometry>
          <mesh>
            <uri>model://nxp_cupcar/meshes/CUPCarCollisionBody.stl</uri>
            <scale>1.0 1.0 1.0</scale>
          </mesh>
        </geometry>
        <material>
          <script>
            <name>Gazebo/DarkGrey</name>
            <uri>file://media/materials/scripts/gazebo.material</uri>
          </script>
        </material>
      </visual>
    {% endif %}
      <collision name='{{ model_name }}_frame_collision'>
        <pose>0 0 0 0 0 1.57079632679</pose>
        <geometry>
          <mesh>
            <uri>model://nxp_cupcar/meshes/CUPCarCollisionBody.stl</uri>
            <scale>1.0 1.0 1.0</scale>
          </mesh>
        </geometry>
      </collision>
    </link>
    <link name='{{ model_name }}_front_left_wheel_link'>
      <pose>-.04 0.07 -.0055 0 0 0</pose>
      <inertial>
        <pose>0 0 0 0 0 0</pose>
        <mass>1.0</mass>
        <inertia>
          <ixx>0.002</ixx>
          <ixy>0</ixy>
          <ixz>0</ixz>
          <iyy>0.002</iyy>
          <iyz>0</iyz>
          <izz>0.002</izz>
        </inertia>
      </inertial>
      <collision name='{{ model_name }}_front_left_wheel_collision'>
        <pose>0 0 0 1.57079632679 0 0</pose>
        <geometry>
          <cylinder>
            <radius>0.033</radius>
            <length>0.022</length>
          </cylinder>
        </geometry>
        <max_contacts>1</max_contacts>
        <surface>
          <friction>
            <ode>
              <mu>1.0</mu>
              <mu2>2.0</mu2>
              <fdir1>1 0 0</fdir1>
              <slip1>0.0</slip1>
              <slip2>0.0</slip2>
            </ode>
          </friction>
          <bounce>
            <restitution_coefficient>0</restitution_coefficient>
            <threshold>1e6</threshold>
          </bounce>
          <contact>
            <ode>
              <min_depth>0.001</min_depth>
              <max_vel>0.0</max_vel>
              <kp>1.0e6</kp>
              <kd>100.0</kd>
            </ode>
          </contact>
        </surface>
      </collision>

    {%- if low_polycountwheel == 1 -%}
      <visual name='{{ model_name }}_front_left_wheel_collision_visual'>
        <pose>0 0 0 1.57079632679 0 0</pose>
        <geometry>
          <cylinder>
            <radius>0.033</radius>
            <length>0.024</length>
          </cylinder>
        </geometry>
        <material>
          <script>
            <name>Gazebo/DarkGrey</name>
            <uri>file://media/materials/scripts/gazebo.material</uri>
          </script>
        </material>
      </visual>
    {% endif %}
    {%- if low_polycountwheel != 1 -%}
      <visual name='{{ model_name }}_front_left_wheel_visual'>
        <pose>0 .006 0 0 0 -1.57079632679</pose>
        <geometry>
          <mesh>
            <uri>model://nxp_cupcar/meshes/LeftWheel.stl</uri>
          </mesh>
        </geometry>
        <material>
          <script>
            <name>Gazebo/Grey</name>
            <uri>file://media/materials/scripts/gazebo.material</uri>
          </script>          
        </material>
      </visual>
    {% endif %}
      <gravity>1</gravity>
      <velocity_decay/>
    </link>
    <link name='{{ model_name }}_front_right_wheel_link'>
      <pose>-.04 -0.07 -.0055 0 0 0</pose>
      <inertial>
        <pose>0 0 0 0 0 0</pose>
        <mass>1.0</mass>
        <inertia>
          <ixx>0.002</ixx>
          <ixy>0</ixy>
          <ixz>0</ixz>
          <iyy>0.002</iyy>
          <iyz>0</iyz>
          <izz>0.002</izz>
        </inertia>
      </inertial>
      <collision name='{{ model_name }}_front_right_wheel_collision'>
        <pose>0 0 0 1.57079632679 0 0</pose>
        <geometry>
          <cylinder>
            <radius>0.033</radius>
            <length>0.022</length>
          </cylinder>
        </geometry>
        <max_contacts>1</max_contacts>
        <surface>
          <friction>
            <ode>
              <mu>1.0</mu>
              <mu2>2.0</mu2>
              <fdir1>1 0 0</fdir1>
              <slip1>0.0</slip1>
              <slip2>0.0</slip2>
            </ode>
          </friction>
          <bounce>
            <restitution_coefficient>0</restitution_coefficient>
            <threshold>1e6</threshold>
          </bounce>
          <contact>
            <ode>
              <min_depth>0.001</min_depth>
              <max_vel>0.0</max_vel>
              <kp>1.0e6</kp>
              <kd>100.0</kd>
            </ode>
          </contact>
        </surface>
      </collision>

    {%- if low_polycountwheel == 1 -%}
      <visual name='{{ model_name }}_front_right_wheel_collision_visual'>
        <pose>0 0 0 1.57079632679 0 0</pose>
        <geometry>
          <cylinder>
            <radius>0.033</radius>
            <length>0.024</length>
          </cylinder>
        </geometry>
        <material>
          <script>
            <name>Gazebo/DarkGrey</name>
            <uri>file://media/materials/scripts/gazebo.material</uri>
          </script>
        </material>
      </visual>
    {% endif %}
    {%- if low_polycountwheel != 1 -%}
      <visual name='{{ model_name }}_front_right_wheel_visual'>
        <pose>0 -.006 0 0 0 1.57079632679</pose>
        <geometry>
          <mesh>
            <uri>model://nxp_cupcar/meshes/RightWheel.stl</uri>
          </mesh>
        </geometry>
        <material>
          <script>
            <name>Gazebo/Grey</name>
            <uri>file://media/materials/scripts/gazebo.material</uri>
          </script>          
        </material>
      </visual>
    {% endif %}
      <gravity>1</gravity>
      <velocity_decay/>
    </link>
    <link name='{{ model_name }}_rear_left_wheel_link'>
      <pose>-.213 0.07 -.0055 0 0 0</pose>
      <inertial>
        <pose>0 0 0 0 0 0</pose>
        <mass>1.0</mass>
        <inertia>
          <ixx>0.002</ixx>
          <ixy>0</ixy>
          <ixz>0</ixz>
          <iyy>0.002</iyy>
          <iyz>0</iyz>
          <izz>0.002</izz>
        </inertia>
      </inertial>
      <collision name='{{ model_name }}_rear_left_wheel_collision'>
        <pose>0 0 0 1.57079632679 0 0</pose>
        <geometry>
          <cylinder>
            <radius>0.033</radius>
            <length>0.022</length>
          </cylinder>
        </geometry>
        <max_contacts>1</max_contacts>
        <surface>
          <friction>
            <ode>
              <mu>0.7</mu>
              <mu2>0.7</mu2>
              <fdir1>1 0 0</fdir1>
              <slip1>0.0</slip1>
              <slip2>0.0</slip2>
            </ode>
          </friction>
          <bounce>
            <restitution_coefficient>0</restitution_coefficient>
            <threshold>1e6</threshold>
          </bounce>
          <contact>
            <ode>
              <min_depth>0.001</min_depth>
              <max_vel>0.0</max_vel>
              <kp>1.0e6</kp>
              <kd>100.0</kd>
            </ode>
          </contact>
        </surface>
      </collision>

    {%- if low_polycountwheel == 1 -%}
      <visual name='{{ model_name }}_rear_left_wheel_collision_visual'>
        <pose>0 0 0 1.57079632679 0 0</pose>
        <geometry>
          <cylinder>
            <radius>0.033</radius>
            <length>0.024</length>
          </cylinder>
        </geometry>
        <material>
          <script>
            <name>Gazebo/DarkGrey</name>
            <uri>file://media/materials/scripts/gazebo.material</uri>
          </script>
        </material>
      </visual>
    {% endif %}
    {%- if low_polycountwheel != 1 -%}
      <visual name='{{ model_name }}_rear_left_wheel_visual'>
        <pose>0 .006 0 0 0 -1.57079632679</pose>
        <geometry>
          <mesh>
            <uri>model://nxp_cupcar/meshes/LeftWheel.stl</uri>
          </mesh>
        </geometry>
        <material>
          <script>
            <name>Gazebo/Grey</name>
            <uri>file://media/materials/scripts/gazebo.material</uri>
          </script>
        </material>
      </visual>
    {% endif %}
      <gravity>1</gravity>
      <velocity_decay/>
    </link>
    <link name='{{ model_name }}_rear_right_wheel_link'>
      <pose>-.213 -0.07 -.0055 0 0 0</pose>
      <inertial>
        <pose>0 0 0 0 0 0</pose>
        <mass>1.0</mass>
        <inertia>
          <ixx>0.002</ixx>
          <ixy>0</ixy>
          <ixz>0</ixz>
          <iyy>0.002</iyy>
          <iyz>0</iyz>
          <izz>0.002</izz>
        </inertia>
      </inertial>
      <collision name='{{ model_name }}_rear_right_wheel_collision'>
        <pose>0 0 0 1.57079632679 0 0</pose>
        <geometry>
          <cylinder>
            <radius>0.033</radius>
            <length>0.022</length>
          </cylinder>
        </geometry>
        <max_contacts>1</max_contacts>
        <surface>
          <friction>
            <ode>
              <mu>0.7</mu>
              <mu2>0.7</mu2>
              <fdir1>1 0 0</fdir1>
              <slip1>0.0</slip1>
              <slip2>0.0</slip2>
            </ode>
          </friction>
          <bounce>
            <restitution_coefficient>0</restitution_coefficient>
            <threshold>1e6</threshold>
          </bounce>
          <contact>
            <ode>
              <min_depth>0.001</min_depth>
              <max_vel>0.0</max_vel>
              <kp>1.0e6</kp>
              <kd>100.0</kd>
            </ode>
          </contact>
        </surface>
      </collision>

    {%- if low_polycountwheel == 1 -%}
      <visual name='{{ model_name }}_rear_right_wheel_collision_visual'>
        <pose>0 0 0 1.57079632679 0 0</pose>
        <geometry>
          <cylinder>
            <radius>0.033</radius>
            <length>0.024</length>
          </cylinder>
        </geometry>
        <material>
          <script>
            <name>Gazebo/DarkGrey</name>
            <uri>file://media/materials/scripts/gazebo.material</uri>
          </script>
        </material>
      </visual>
    {% endif %}
    {%- if low_polycountwheel != 1 -%}
      <visual name='{{ model_name }}_rear_right_wheel_visual'>
        <pose>0 -.006 0 0 0 1.57079632679</pose>
        <geometry>
          <mesh>
            <uri>model://nxp_cupcar/meshes/RightWheel.stl</uri>
          </mesh>
        </geometry>
        <material>
          <script>
            <name>Gazebo/Grey</name>
            <uri>file://media/materials/scripts/gazebo.material</uri>
          </script>
        </material>
      </visual>
    {% endif %}
      <gravity>1</gravity>
      <velocity_decay/>
    </link>
    <link name='{{ model_name }}_front_right_wheel_steering_link'>
      <pose>-.04 -0.06 -.0055 0 0 0</pose>
      <inertial>
        <mass>0.1</mass>
        <inertia>
          <ixx>0.001</ixx>
          <ixy>0.0</ixy>
          <iyy>0.001</iyy>
          <ixz>0.0</ixz>
          <iyz>0.0</iyz>
          <izz>0.001</izz>
        </inertia>
      </inertial>
      <gravity>1</gravity>
      <velocity_decay/>
    </link>
    <link name='{{ model_name }}_front_left_wheel_steering_link'>
      <pose>-.04 0.06 -.0055 0 0 0</pose>
      <inertial>
        <mass>0.1</mass>
        <inertia>
          <ixx>0.001</ixx>
          <ixy>0.0</ixy>
          <iyy>0.001</iyy>
          <ixz>0.0</ixz>
          <iyz>0.0</iyz>
          <izz>0.001</izz>
        </inertia>
      </inertial>
      <gravity>1</gravity>
      <velocity_decay/>
    </link>
    <joint type='revolute' name='{{ model_name }}_front_left_steering_joint'>
      <child>{{ model_name }}_front_left_wheel_steering_link</child>
      <parent>{{ model_name }}_frame_link</parent>
      <axis>
        <xyz>0 0 1</xyz>
        <limit>
          <lower>-0.7727</lower>
          <upper>0.7727</upper>
        </limit>
        <dynamics>
          <friction>.1</friction>
          <damping>0.5</damping>
          <spring_reference>0</spring_reference>
          <spring_stiffness>0</spring_stiffness>
        </dynamics>
        <use_parent_model_frame>true</use_parent_model_frame>
      </axis>
    </joint>
    <joint type='revolute' name='{{ model_name }}_front_right_steering_joint'>
      <child>{{ model_name }}_front_right_wheel_steering_link</child>
      <parent>{{ model_name }}_frame_link</parent>
      <axis>
        <xyz>0 0 1</xyz>
        <limit>
          <lower>-0.7727</lower>
          <upper>0.7727</upper>
        </limit>
        <dynamics>
          <friction>.1</friction>
          <damping>0.5</damping>
          <spring_reference>0</spring_reference>
          <spring_stiffness>0</spring_stiffness>
        </dynamics>
        <use_parent_model_frame>true</use_parent_model_frame>
      </axis>
    </joint>
    <joint type='revolute' name='{{ model_name }}_front_left_wheel_joint'>
      <child>{{ model_name }}_front_left_wheel_link</child>
      <parent>{{ model_name }}_front_left_wheel_steering_link</parent>
      <axis>
        <xyz>0 1 0</xyz>
        <limit>
          <lower>-1e+16</lower>
          <upper>1e+16</upper>
        </limit>
        <dynamics>
          <spring_reference>0</spring_reference>
          <spring_stiffness>0</spring_stiffness>
        </dynamics>
        <use_parent_model_frame>1</use_parent_model_frame>
      </axis>
    </joint>
    <joint type='revolute' name='{{ model_name }}_front_right_wheel_joint'>
      <child>{{ model_name }}_front_right_wheel_link</child>
      <parent>{{ model_name }}_front_right_wheel_steering_link</parent>
      <axis>
        <xyz>0 1 0</xyz>
        <limit>
          <lower>-1e+16</lower>
          <upper>1e+16</upper>
        </limit>
        <dynamics>
          <spring_reference>0</spring_reference>
          <spring_stiffness>0</spring_stiffness>
        </dynamics>
        <use_parent_model_frame>1</use_parent_model_frame>
      </axis>
    </joint>
    <joint type='revolute' name='{{ model_name }}_rear_left_wheel_joint'>
      <child>{{ model_name }}_rear_left_wheel_link</child>
      <parent>{{ model_name }}_frame_link</parent>
      <axis>
        <xyz>0 1 0</xyz>
        <limit>
          <lower>-1e+16</lower>
          <upper>1e+16</upper>
        </limit>
        <dynamics>
          <spring_reference>0</spring_reference>
          <spring_stiffness>0</spring_stiffness>
        </dynamics>
        <use_parent_model_frame>1</use_parent_model_frame>
      </axis>
    </joint>
    <joint type='revolute' name='{{ model_name }}_rear_right_wheel_joint'>
      <child>{{ model_name }}_rear_right_wheel_link</child>
      <parent>{{ model_name }}_frame_link</parent>
      <axis>
        <xyz>0 1 0</xyz>
        <limit>
          <lower>-1e+16</lower>
          <upper>1e+16</upper>
        </limit>
        <dynamics>
          <spring_reference>0</spring_reference>
          <spring_stiffness>0</spring_stiffness>
        </dynamics>
        <use_parent_model_frame>1</use_parent_model_frame>
      </axis>
    </joint>
    <link name='{{ model_name }}/imu_link'>
      <pose>-.15 0 .05 0 0 0</pose>
      <inertial>
        <pose>0 0 0 0 0 0</pose>
        <mass>0.015</mass>
        <inertia>
          <ixx>1e-05</ixx>
          <ixy>0</ixy>
          <ixz>0</ixz>
          <iyy>1e-05</iyy>
          <iyz>0</iyz>
          <izz>1e-05</izz>
        </inertia>
      </inertial>
      <gravity>1</gravity>
      <velocity_decay/>
    </link>
    <joint name='{{ model_name }}/imu_joint' type='revolute'>
      <child>{{ model_name }}/imu_link</child>
      <parent>{{ model_name }}_frame_link</parent>
      <axis>
        <xyz>1 0 0</xyz>
        <limit>
          <lower>0</lower>
          <upper>0</upper>
          <effort>0</effort>
          <velocity>0</velocity>
        </limit>
        <dynamics>
          <spring_reference>0</spring_reference>
          <spring_stiffness>0</spring_stiffness>
        </dynamics>
        <use_parent_model_frame>1</use_parent_model_frame>
      </axis>
    </joint>
    <include>
      <uri>model://gps</uri>
      <pose>-.15 0 .05 0 0 0</pose>
      <name>gps</name>
    </include>
    <joint name='gps_joint' type='fixed'>
      <child>gps::link</child>
      <parent>{{ model_name }}_frame_link</parent>
    </joint>

  {%- if pixy2_cmucam5 == 1 -%}
    <include>
      <uri>model://pixy2_cmucam5</uri>
      <pose>-.15 0 .15 0 0 0</pose>
      <name>pixy2_cmucam5</name>
    </include>
    <joint name='pixy2_cmucam5_joint' type='fixed'>
      <child>pixy2_cmucam5::Pixy2CMUcam5_link</child>
      <parent>nxp_cupcar_frame_link</parent>
    </joint>
  {% endif %}  
    <plugin name='barometer_plugin' filename='libgazebo_barometer_plugin.so'>
      <robotNamespace/>
      <pubRate>50</pubRate>
      <baroTopic>/baro</baroTopic>
    </plugin>
    <plugin name='gazebo_imu_plugin' filename='libgazebo_imu_plugin.so'>
      <robotNamespace></robotNamespace>
      <linkName>{{ model_name }}/imu_link</linkName>
      <imuTopic>/imu</imuTopic>
      <gyroscopeNoiseDensity>0.0003394</gyroscopeNoiseDensity>
      <gyroscopeRandomWalk>3.8785e-05</gyroscopeRandomWalk>
      <gyroscopeBiasCorrelationTime>1000.0</gyroscopeBiasCorrelationTime>
      <gyroscopeTurnOnBiasSigma>0.0087</gyroscopeTurnOnBiasSigma>
      <accelerometerNoiseDensity>0.004</accelerometerNoiseDensity>
      <accelerometerRandomWalk>0.006</accelerometerRandomWalk>
      <accelerometerBiasCorrelationTime>300.0</accelerometerBiasCorrelationTime>
      <accelerometerTurnOnBiasSigma>0.196</accelerometerTurnOnBiasSigma>
    </plugin>
    <plugin name='groundtruth_plugin' filename='libgazebo_groundtruth_plugin.so'>
      <robotNamespace/>
    </plugin>
    <plugin name='magnetometer_plugin' filename='libgazebo_magnetometer_plugin.so'>
      <robotNamespace/>
      <pubRate>100</pubRate>
      <noiseDensity>0.0004</noiseDensity>
      <randomWalk>6.4e-06</randomWalk>
      <biasCorrelationTime>600</biasCorrelationTime>
      <magTopic>/mag</magTopic>
    </plugin>
    <plugin name='mavlink_interface' filename='libgazebo_mavlink_interface.so'>
      <robotNamespace/>
      <imuSubTopic>/imu</imuSubTopic>
      <magSubTopic>/mag</magSubTopic>
      <gpsSubTopic>/gps</gpsSubTopic>
      <baroSubTopic>/baro</baroSubTopic>
      <mavlink_addr>INADDR_ANY</mavlink_addr>
      <mavlink_udp_port>{{ mavlink_udp_port }}</mavlink_udp_port>
      <mavlink_tcp_port>{{ mavlink_tcp_port }}</mavlink_tcp_port>
      <serialEnabled>{{ serial_enabled }}</serialEnabled>
      <serialDevice>{{ serial_device }}</serialDevice>
      <baudRate>{{ serial_baudrate }}</baudRate>
      <qgc_addr>INADDR_ANY</qgc_addr>
      <qgc_udp_port>14550</qgc_udp_port>
      <sdk_addr>INADDR_ANY</sdk_addr>
      <sdk_udp_port>14540</sdk_udp_port>
      <hil_mode>{{ hil_mode }}</hil_mode>
      <hil_state_level>0</hil_state_level>
      <send_vision_estimation>0</send_vision_estimation>
      <send_odometry>1</send_odometry>
      <enable_lockstep>{{ enable_lockstep }}</enable_lockstep>
      <use_tcp>1</use_tcp>
      <motorSpeedCommandPubTopic>/gazebo/command/motor_speed</motorSpeedCommandPubTopic>
      <control_channels>
        <channel name='{{ model_name }}_rear_left_wheel_drive'>
          <input_index>5</input_index>
          <input_offset>0</input_offset>
          <input_scaling>40</input_scaling>
          <zero_position_disarmed>0</zero_position_disarmed>
          <zero_position_armed>0</zero_position_armed>
          <joint_control_type>velocity</joint_control_type>
          <joint_name>{{ model_name }}_rear_left_wheel_joint</joint_name>
          <joint_control_pid>
            <p>0.1</p>
            <i>0</i>
            <d>0</d>
            <iMax>800</iMax>
            <iMin>-800</iMin>
            <cmdMax>1200</cmdMax>
            <cmdMin>-1200</cmdMin>
          </joint_control_pid>
        </channel>
        <channel name='{{ model_name }}_rear_right_wheel_drive'>
          <input_index>6</input_index>
          <input_offset>0</input_offset>
          <input_scaling>40</input_scaling>
          <zero_position_disarmed>0</zero_position_disarmed>
          <zero_position_armed>0</zero_position_armed>
          <joint_control_type>velocity</joint_control_type>
          <joint_name>{{ model_name }}_rear_right_wheel_joint</joint_name>
          <joint_control_pid>
            <p>0.1</p>
            <i>0</i>
            <d>0</d>
            <iMax>800</iMax>
            <iMin>-800</iMin>
            <cmdMax>1200</cmdMax>
            <cmdMin>-1200</cmdMin>
          </joint_control_pid>
        </channel>
        <channel name='{{ model_name }}_left_wheel_steering'>
          <input_index>0</input_index>
          <input_offset>0</input_offset>
          <input_scaling>1</input_scaling>
          <zero_position_disarmed>0</zero_position_disarmed>
          <zero_position_armed>0</zero_position_armed>
          <joint_control_type>position</joint_control_type>
          <joint_name>{{ model_name }}_front_left_steering_joint</joint_name>
          <joint_control_pid>
            <p>5.0</p>
            <i>0</i>
            <d>0</d>
            <iMax>40</iMax>
            <iMin>-40</iMin>
            <cmdMax>80</cmdMax>
            <cmdMin>-80</cmdMin>
          </joint_control_pid>
        </channel>
        <channel name='{{ model_name }}_right_wheel_steering'>
          <input_index>1</input_index>
          <input_offset>0</input_offset>
          <input_scaling>1</input_scaling>
          <zero_position_disarmed>0</zero_position_disarmed>
          <zero_position_armed>0</zero_position_armed>
          <joint_control_type>position</joint_control_type>
          <joint_name>{{ model_name }}_front_right_steering_joint</joint_name>
          <joint_control_pid>
            <p>5.0</p>
            <i>0</i>
            <d>0</d>
            <iMax>40</iMax>
            <iMin>-40</iMin>
            <cmdMax>80</cmdMax>
            <cmdMin>-80</cmdMin>
          </joint_control_pid>
        </channel>
      </control_channels>
    </plugin>
  </model>
</sdf>
