<?xml version="1.0"?>
<sdf version="1.6">
  <model name="nxp_cupcar">
    <pose>0 0 0.003 0 0 0</pose>
    <link name="chassis">
      <pose>0 0 0 0 0 1.57</pose>
      <inertial>
        <mass>20.0</mass>
        <inertia>
          <ixx>0.12083</ixx>
          <ixy>0.0</ixy>
          <iyy>0.03333</iyy>
          <ixz>0.0</ixz>
          <iyz>0.0</iyz>
          <izz>0.12083</izz>
        </inertia>
      </inertial>

      <visual name="chassis">
        <pose>0.0 0.005 0.0625 0 0 0</pose>
        <geometry>
          <box>
            <size>0.17526 0.21 0.095</size>
          </box>
        </geometry>
        <material>
          <script>
            <name>Gazebo/Green</name>
            <uri>file://media/materials/scripts/gazebo.material</uri>
          </script>
        </material>
      </visual>

      <visual name="front_bumper">
        <pose>0.0 -0.20 0.0458488 0.0 0 0</pose>
        <geometry>
          <box>
            <size>0.1337282 0.048 0.0566691</size>
          </box>
        </geometry>
        <material>
          <script>
            <name>Gazebo/Green</name>
            <uri>file://media/materials/scripts/gazebo.material</uri>
          </script>
        </material>
      </visual>

      <visual name="hood">
        <pose>0.0 -0.1900842 0.0676305 0.341247 0 0</pose>
        <geometry>
          <box>
            <size>0.1597968 0.0493107 0.0265468</size>
          </box>
        </geometry>
        <material>
          <script>
            <name>Gazebo/Green</name>
            <uri>file://media/materials/scripts/gazebo.material</uri>
          </script>
        </material>
      </visual>

      <visual name="windshield">
        <pose>0.0 -0.0875105 0.1032268 0.335476 0 0</pose>
        <geometry>
          <box>
            <size>0.1168381 0.1654253 0.0272347</size>
          </box>
        </geometry>
        <material>
          <script>
            <name>Gazebo/Green</name>
            <uri>file://media/materials/scripts/gazebo.material</uri>
          </script>
        </material>
      </visual>

      <visual name="top_front">
        <pose>0.0 0.0161236 0.1386042 0.135030 0 0</pose>
        <geometry>
          <box>
            <size>0.1279154 0.0625988 0.0171868</size>
          </box>
        </geometry>
        <material>
          <script>
            <name>Gazebo/Green</name>
            <uri>file://media/materials/scripts/gazebo.material</uri>
          </script>
        </material>
      </visual>

      <visual name="top_rear">
        <pose>0.0 0.0817696 0.1360069 -0.068997 0 0</pose>
        <geometry>
          <box>
            <size>0.1285130 0.0771189 0.0226557</size>
          </box>
        </geometry>
        <material>
          <script>
            <name>Gazebo/Green</name>
            <uri>file://media/materials/scripts/gazebo.material</uri>
          </script>
        </material>
      </visual>

      <visual name="rear_window">
        <pose>0.0 0.1640531 0.1175126 -0.262017 0 0</pose>
        <geometry>
          <box>
            <size>0.1267845 0.1116344 0.0244286</size>
          </box>
        </geometry>
        <material>
          <script>
            <name>Gazebo/Green</name>
            <uri>file://media/materials/scripts/gazebo.material</uri>
          </script>
        </material>
      </visual>

      <visual name="trunk">
        <pose>0.0 0.1637059 0.0888180 0.0 0 0</pose>
        <geometry>
          <box>
            <size>0.1788064 0.1138988 0.0482746</size>
          </box>
        </geometry>
        <material>
          <script>
            <name>Gazebo/Green</name>
            <uri>file://media/materials/scripts/gazebo.material</uri>
          </script>
        </material>
      </visual>

      <visual name="back_bumper">
        <pose>0.0 0.2054454 0.0577870 0.0 0 0</pose>
        <geometry>
          <box>
            <size>0.1781650 0.0512093 0.0581427</size>
          </box>
        </geometry>
        <material>
          <script>
            <name>Gazebo/Green</name>
            <uri>file://media/materials/scripts/gazebo.material</uri>
          </script>
        </material>
      </visual>

      <collision name="chassis">
        <pose>0.0 0.005 0.0625 0 0 0</pose>
        <geometry>
          <box>
            <size>0.17526 0.21 0.095</size>
          </box>
        </geometry>
      </collision>

      <collision name="front_bumper">
        <pose>0.0 -0.20 0.0458488 0.0 0 0</pose>
        <geometry>
          <box>
            <size>0.1337282 0.048 0.0566691</size>
          </box>
        </geometry>
      </collision>

      <collision name="hood">
        <pose>0.0 -0.1900842 0.0676305 0.341247 0 0</pose>
        <geometry>
          <box>
            <size>0.1597968 0.0493107 0.0265468</size>
          </box>
        </geometry>
      </collision>

      <collision name="windshield">
        <pose>0.0 -0.0875105 0.1032268 0.335476 0 0</pose>
        <geometry>
          <box>
            <size>0.1168381 0.1654253 0.0272347</size>
          </box>
        </geometry>
      </collision>

      <collision name="top_front">
        <pose>0.0 0.0161236 0.1386042 0.135030 0 0</pose>
        <geometry>
          <box>
            <size>0.1279154 0.0625988 0.0171868</size>
          </box>
        </geometry>
      </collision>

      <collision name="top_rear">
        <pose>0.0 0.0817696 0.1360069 -0.068997 0 0</pose>
        <geometry>
          <box>
            <size>0.1285130 0.0771189 0.0226557</size>
          </box>
        </geometry>
      </collision>

      <collision name="rear_window">
        <pose>0.0 0.1640531 0.1175126 -0.262017 0 0</pose>
        <geometry>
          <box>
            <size>0.1267845 0.116344 0.0244286</size>
          </box>
        </geometry>
      </collision>

      <collision name="trunk">
        <pose>0.0 0.1637059 0.0888180 0.0 0 0</pose>
        <geometry>
          <box>
            <size>0.1788064 0.1138988 0.0482746</size>
          </box>
        </geometry>
      </collision>

      <collision name="back_bumper">
        <pose>0.0 .2054454 0.0577870 0.0 0 0</pose>
        <geometry>
          <box>
            <size>0.1781650 0.0512093 0.0581427</size>
          </box>
        </geometry>
      </collision>
    </link>

    <link name="steering_wheel">
      <pose>0.0627868 0.0357734 0.0988243 -0.1302101 0 1.57</pose>
      <inertial>
        <mass>0.1</mass>
        <inertia>
          <ixx>0.014583300</ixx>
          <ixy>0</ixy>
          <ixz>0</ixz>
          <iyy>0.014583300</iyy>
          <iyz>0</iyz>
          <izz>0.012500000</izz>
        </inertia>
      </inertial>
      <collision name="collision">
        <geometry>
          <cylinder>
            <radius>0.0178172</radius>
            <length>0.0041845</length>
          </cylinder>
        </geometry>
        <surface>
          <contact>
            <ode>
              <min_depth>0.003</min_depth>
            </ode>
          </contact>
        </surface>
      </collision>
      <visual name="visual">
        <pose>0 0 0 0.1302101 0 0</pose>
        <geometry>
          <mesh>
            <uri>model://prius_hybrid/meshes/Hybrid.obj</uri>
            <scale>0.001 0.001 0.001</scale>
            <submesh>
              <name>Steering_Wheel</name>
              <center>true</center>
            </submesh>
          </mesh>
        </geometry>
      </visual>
    </link>

    <link name="front_left_wheel">
      <pose>.141 0.076 0.03 0 0 1.57</pose>
      <inertial>
        <mass>1.1</mass>
        <inertia>
          <ixx>0.058631238</ixx>
          <ixy>0.0</ixy>
          <iyy>0.033552910</iyy>
          <ixz>0.0</ixz>
          <iyz>0.0</iyz>
          <izz>0.033552910</izz>
        </inertia>
      </inertial>

      <visual name="collision_visual">
        <pose>0.0 0.0 0.0 0 1.5707963267948966 0</pose>
        <geometry>
          <cylinder>
            <radius>0.033</radius>
            <length>0.01</length>
          </cylinder>
        </geometry>
        <material>
          <script>
            <name>Gazebo/Green</name>
            <uri>file://media/materials/scripts/gazebo.material</uri>
          </script>
        </material>
      </visual>

      <collision name="collision">
        <pose>0.0 0.0 0.0 0 1.5707963267948966 0</pose>
        <geometry>
          <sphere>
            <radius>0.033</radius>
          </sphere>
        </geometry>
        <surface>
          <friction>
            <ode>
              <mu>1.0</mu>
              <mu2>2.0</mu2>
              <fdir1>1 .3 .3</fdir1>
              <slip1>0.0</slip1>
              <slip2>0.0</slip2>
            </ode>
          </friction>
          <contact>
            <ode>
              <min_depth>0.001</min_depth>
              <kp>1e9</kp>
            </ode>
          </contact>
        </surface>

      </collision>
    </link>

    <link name="front_right_wheel">
      <pose>0.141 -0.076 0.03 0 0 1.57</pose>
      <inertial>
        <mass>1.1</mass>
        <inertia>
          <ixx>0.058631238</ixx>
          <ixy>0.0</ixy>
          <iyy>0.033552910</iyy>
          <ixz>0.0</ixz>
          <iyz>0.0</iyz>
          <izz>0.033552910</izz>
        </inertia>
      </inertial>

      <visual name="collision_visual">
        <pose>0.0 0.0 0.0 0 1.5707963267948966 0</pose>
        <geometry>
          <cylinder>
            <radius>0.033</radius>
            <length>0.01</length>
          </cylinder>
        </geometry>
        <material>
          <script>
            <name>Gazebo/Green</name>
            <uri>file://media/materials/scripts/gazebo.material</uri>
          </script>
        </material>
      </visual>

      <collision name="collision">
        <pose>0.0 0.0 0.0 0 1.5707963267948966 0</pose>
        <geometry>
          <sphere>
            <radius>0.033</radius>
          </sphere>
        </geometry>
        <surface>
          <friction>
            <ode>
              <mu>1.0</mu>
              <mu2>2.0</mu2>
              <fdir1>1 .3 .3</fdir1>
              <slip1>0.0</slip1>
              <slip2>0.0</slip2>
            </ode>
          </friction>
          <contact>
            <ode>
              <min_depth>0.001</min_depth>
              <kp>1e9</kp>
            </ode>
          </contact>
        </surface>

      </collision>
    </link>


    <link name="rear_left_wheel">
      <pose>-0.145 0.0786 0.03 0 0 1.57</pose>
      <inertial>
        <mass>1.1</mass>
        <inertia>
          <ixx>0.058631238</ixx>
          <ixy>0.0</ixy>
          <iyy>0.033552910</iyy>
          <ixz>0.0</ixz>
          <iyz>0.0</iyz>
          <izz>0.033552910</izz>
        </inertia>
      </inertial>

      <visual name="collision_visual">
        <pose>0.0 0.0 0.0 0 1.5707963267948966 0</pose>
        <geometry>
          <cylinder>
            <radius>0.033</radius>
            <length>0.01</length>
          </cylinder>
        </geometry>
        <material>
          <script>
            <name>Gazebo/Green</name>
            <uri>file://media/materials/scripts/gazebo.material</uri>
          </script>
        </material>
      </visual>

      <collision name="collision">
        <pose>0.0 0.0 0.0 0 1.5707963267948966 0</pose>
        <geometry>
          <sphere>
            <radius>0.033</radius>
          </sphere>
        </geometry>
        <surface>
          <friction>
            <ode>
              <mu>1.0</mu>
              <mu2>2.0</mu2>
              <fdir1>1 .3 .3</fdir1>
              <slip1>0.0</slip1>
              <slip2>0.0</slip2>
            </ode>
          </friction>
          <contact>
            <ode>
              <min_depth>0.001</min_depth>
              <kp>1e9</kp>
            </ode>
          </contact>
        </surface>

      </collision>
    </link>

    <link name="rear_right_wheel">
      <pose>-0.145 -0.0786 0.03 0 0 1.57</pose>
      <inertial>
        <mass>1.1</mass>
        <inertia>
          <ixx>0.058631238</ixx>
          <ixy>0.0</ixy>
          <iyy>0.033552910</iyy>
          <ixz>0.0</ixz>
          <iyz>0.0</iyz>
          <izz>0.033552910</izz>
        </inertia>
      </inertial>
      
      <!-- <visual name="visual">
        <pose>-0.04 0.0 0.0 0 0 0</pose>
        <geometry>
          <mesh>
            <uri>model://prius_hybrid/meshes/Hybrid.obj</uri>
            <scale>0.01 0.01 0.01</scale>
            <submesh>
              <name>Wheel_Front_Right</name>
              <center>true</center>
            </submesh>
          </mesh>
        </geometry>
      </visual> -->

      <visual name="collision_visual">
        <pose>0.0 0.0 0.0 0 1.5707963267948966 0</pose>
        <geometry>
          <cylinder>
            <radius>0.033</radius>
            <length>0.01</length>
          </cylinder>
        </geometry>
        <material>
          <script>
            <name>Gazebo/Green</name>
            <uri>file://media/materials/scripts/gazebo.material</uri>
          </script>
        </material>
      </visual>

      <collision name="collision">
        <pose>0.0 0.0 0.0 0 1.5707963267948966 0</pose>
        <geometry>
          <sphere>
            <radius>0.033</radius>
          </sphere>
        </geometry>
        <surface>
          <friction>
            <ode>
              <mu>1.0</mu>
              <mu2>2.0</mu2>
              <fdir1>1 .3 .3</fdir1>
              <slip1>0.0</slip1>
              <slip2>0.0</slip2>
            </ode>
          </friction>
          <contact>
            <ode>
              <min_depth>0.001</min_depth>
              <kp>1e9</kp>
            </ode>
          </contact>
        </surface>
      </collision>
    </link>

    <joint type="universal" name="front_left_combined_joint">
      <pose>0 0 0 0 0 0</pose>
      <child>front_left_wheel</child>
      <parent>chassis</parent>
      <axis>
        <xyz>0 0 1</xyz>
        <limit>
          <lower>-0.8727</lower>
          <upper>0.8727</upper>
        </limit>
        <dynamics>
          <damping>1.0</damping>
        </dynamics>
      </axis>
      <axis2>
        <xyz>1 0 0</xyz>
        <dynamics>
          <friction>1.0</friction>
        </dynamics>
      </axis2>
    </joint>

    <joint type="universal" name="front_right_combined_joint">
      <pose>0 0 0 0 0 0</pose>
      <child>front_right_wheel</child>
      <parent>chassis</parent>
      <axis>
        <xyz>0 0 1</xyz>
        <limit>
          <lower>-0.8727</lower>
          <upper>0.8727</upper>
        </limit>
        <dynamics>
          <damping>1.0</damping>
        </dynamics>
      </axis>
      <axis2>
        <xyz>1 0 0</xyz>
        <dynamics>
          <friction>1.0</friction>
        </dynamics>
      </axis2>
    </joint>
    <joint type="revolute" name="rear_left_wheel_joint">
      <child>rear_left_wheel</child>
      <parent>chassis</parent>
      <axis>
        <xyz>1 0 0</xyz>
        <dynamics>
          <friction>0.12031606150200002</friction>
        </dynamics>
      </axis>
    </joint>
    <joint type="revolute" name="rear_right_wheel_joint">
      <child>rear_right_wheel</child>
      <parent>chassis</parent>
      <axis>
        <xyz>1 0 0</xyz>
        <dynamics>
          <friction>0.12031606150200002</friction>
        </dynamics>
      </axis>
    </joint>

    <joint name="steering_joint" type="revolute">
      <pose>-0.002 0 0 0 0 0</pose>
      <parent>chassis</parent>
      <child>steering_wheel</child>
      <axis>
        <xyz>-0.964118 0.000768 0.265556</xyz>
        <limit>
          <lower>-7.85</lower>
          <upper>7.85</upper>
        </limit>
        <dynamics>
          <damping>1.0</damping>
        </dynamics>
        <use_parent_model_frame>true</use_parent_model_frame>
      </axis>
      <physics>
        <ode>
          <cfm_damping>1</cfm_damping>
        </ode>
      </physics>
    </joint>

    <plugin name='ackermann_drive' filename='libgazebo_ros_ackermann_drive.so'>
      <ros>
        <namespace>demo</namespace>
        <remapping>cmd_vel:=cmd_demo</remapping>
        <remapping>odom:=odom_demo</remapping>
        <remapping>distance:=distance_demo</remapping>
      </ros>
      <update_rate>100.0</update_rate>
      <front_left_joint>front_left_combined_joint</front_left_joint>
      <front_right_joint>front_right_combined_joint</front_right_joint>
      <rear_left_joint>rear_left_wheel_joint</rear_left_joint>
      <rear_right_joint>rear_right_wheel_joint</rear_right_joint>
      <left_steering_joint>front_left_combined_joint</left_steering_joint>
      <right_steering_joint>front_right_combined_joint</right_steering_joint>
      <steering_wheel_joint>steering_joint</steering_wheel_joint>
      <max_steer>0.6458</max_steer>
      <max_steering_angle>7.85</max_steering_angle>
      <max_speed>5</max_speed>
      <left_steering_pid_gain>15 0 1</left_steering_pid_gain>
      <left_steering_i_range>0 0</left_steering_i_range>
      <right_steering_pid_gain>15 0 1</right_steering_pid_gain>
      <right_steering_i_range>0 0</right_steering_i_range>
      <linear_velocity_pid_gain>1 0 .1</linear_velocity_pid_gain>
      <linear_velocity_i_range>0 0</linear_velocity_i_range>
      <publish_odom>true</publish_odom>
      <publish_odom_tf>true</publish_odom_tf>
      <publish_wheel_tf>true</publish_wheel_tf>
      <publish_distance>true</publish_distance>
      <odometry_frame>odom_demo</odometry_frame>
      <robot_base_frame>chassis</robot_base_frame>
    </plugin>
  </model>
</sdf>
